<?xml version='1.0' encoding='utf-8'?>
<robot name="fromreal">
    <link name="base">
        <inertial>
            <origin xyz="1.072226500022598e-17 0.0 0.026999999999999996" rpy="0.0 0.0 0.0" />
            <mass value="3.3293028146417827" />
            <inertia ixx="0.002889834843108983" iyy="0.002889834843109096" izz="0.004161628518302171" ixy="-1.4279066817834973e-18" iyz="-1.4279066817834973e-18" ixz="2.4988366931211174e-19" />
        </inertial>
        <visual name="base_visual">
            <origin xyz="0.0 0.0 0.0" rpy="0.0 0.0 0.0" />
            <geometry>
                <mesh filename="meshes/base.stl" scale="0.001 0.001 0.001" />
            </geometry>
        </visual>
        <collision name="base_collision">
            <origin xyz="0.0 0.0 0.0" rpy="0.0 0.0 0.0" />
            <geometry>
                <mesh filename="meshes/base.stl" scale="0.001 0.001 0.001" />
            </geometry>
        </collision>
    </link>
    <link name="firstlink">
        <inertial>
            <origin xyz="-0.00172434231072918 -1.2157224286626961e-17 0.037295575963900304" rpy="0.0 -0.0 0.0" />
            <mass value="0.7340834182819004" />
            <inertia ixx="0.00041942282890442776" iyy="0.0004213867444519837" izz="0.0001487805992039362" ixy="-1.6309958580311096e-19" iyz="-3.6853893029344523e-19" ixz="3.6814526047972615e-05" />
        </inertial>
        <visual name="firstlink_visual">
            <origin xyz="0.0 0.0 -0.054000000000000006" rpy="0.0 -0.0 0.0" />
            <geometry>
                <mesh filename="meshes/firstlink.stl" scale="0.001 0.001 0.001" />
            </geometry>
        </visual>
        <collision name="firstlink_collision">
            <origin xyz="0.0 0.0 -0.054000000000000006" rpy="0.0 -0.0 0.0" />
            <geometry>
                <mesh filename="meshes/firstlink.stl" scale="0.001 0.001 0.001" />
            </geometry>
        </collision>
    </link>
    <link name="secondlink">
        <inertial>
            <origin xyz="0.06700000000000006 -2.7113860235213416e-18 0.02211303895168835" rpy="0.0 -0.0 0.0" />
            <mass value="1.6457296533446952" />
            <inertia ixx="0.0003640031924739299" iyy="0.0038482676424804393" izz="0.0038134103806754527" ixy="-1.0709300113376245e-19" iyz="-9.428820118701856e-21" ixz="0.0" />
        </inertial>
        <visual name="secondlink_visual">
            <origin xyz="-0.11699999999999999 0.0 -0.02" rpy="-0.0 1.5707963267948966 0" />
            <geometry>
                <mesh filename="meshes/secondlink.stl" scale="0.001 0.001 0.001" />
            </geometry>
        </visual>
        <collision name="secondlink_collision">
            <origin xyz="-0.11699999999999999 0.0 -0.02" rpy="-0.0 1.5707963267948966 0" />
            <geometry>
                <mesh filename="meshes/secondlink.stl" scale="0.001 0.001 0.001" />
            </geometry>
        </collision>
    </link>
    <link name="thirdlink">
        <inertial>
            <origin xyz="0.04299876058110559 -6.333959057013102e-18 0.0340024788377889" rpy="0.0 -0.0 0.0" />
            <mass value="1.408979230970169" />
            <inertia ixx="0.0004038177266924337" iyy="0.0022510174373775865" izz="0.00212899555687919" ixy="-1.1958607849029235e-18" iyz="-3.0345229206050464e-19" ixz="-0.00023677487512008613" />
        </inertial>
        <visual name="thirdlink_visual">
            <origin xyz="-0.251 0.0 0.02" rpy="-3.141592653589793 -1.5707963267948966 0" />
            <geometry>
                <mesh filename="meshes/thirdlink.stl" scale="0.001 0.001 0.001" />
            </geometry>
        </visual>
        <collision name="thirdlink_collision">
            <origin xyz="-0.251 0.0 0.02" rpy="-3.141592653589793 -1.5707963267948966 0" />
            <geometry>
                <mesh filename="meshes/thirdlink.stl" scale="0.001 0.001 0.001" />
            </geometry>
        </collision>
    </link>
    <link name="forthlink">
        <inertial>
            <origin xyz="0.041202125920307114 -0.0003829964793528957 0.018743550617315207" rpy="0.0 -0.0 0.0" />
            <mass value="0.9400215732663385" />
            <inertia ixx="0.00017340795132844575" iyy="0.0010216031015102545" izz="0.0010207377323847855" ixy="1.2627973554254872e-05" iyz="4.5235313001512305e-07" ixz="-5.222271216434506e-05" />
        </inertial>
        <visual name="forthlink_visual">
            <origin xyz="-0.35100000000000003 0.0 0.0" rpy="-0.0 1.5707963267948966 0" />
            <geometry>
                <mesh filename="meshes/forthlink.stl" scale="0.001 0.001 0.001" />
            </geometry>
        </visual>
        <collision name="forthlink_collision">
            <origin xyz="-0.35100000000000003 0.0 0.0" rpy="-0.0 1.5707963267948966 0" />
            <geometry>
                <mesh filename="meshes/forthlink.stl" scale="0.001 0.001 0.001" />
            </geometry>
        </collision>
    </link>
    <link name="endeffector">
        <inertial>
            <origin xyz="1.361133428190442e-14 3.983895169312746e-10 0.00024999659289512974" rpy="0.0 -0.0 0.0" />
            <mass value="2.7744190122016414e-05" />
            <inertia ixx="1.6184111203829598e-11" iyy="1.6184110789143413e-11" izz="3.1212213396703795e-11" ixy="5.524069406627677e-21" iyz="-7.986794421567882e-19" ixz="4.1626848744132255e-21" />
        </inertial>
        <visual name="endeffector_visual">
            <origin xyz="0.02 0.2670111521025486 -0.39074331580506644" rpy="0.645771823237902 -0.0 0.0" />
            <geometry>
                <mesh filename="meshes/endeffector.stl" scale="0.001 0.001 0.001" />
            </geometry>
        </visual>
        <collision name="endeffector_collision">
            <origin xyz="0.02 0.2670111521025486 -0.39074331580506644" rpy="0.645771823237902 -0.0 0.0" />
            <geometry>
                <mesh filename="meshes/endeffector.stl" scale="0.001 0.001 0.001" />
            </geometry>
        </collision>
    </link>
    <joint name="base_Revolute-1" type="revolute">
        <origin xyz="0.0 0.0 0.054000000000000006" rpy="0.0 -0.0 0.0" />
        <parent link="base" />
        <child link="firstlink" />
        <axis xyz="0.0 0.0 1.0" />
        <limit lower="-1.570796" upper="1.570796" effort="1000000" velocity="1000000" />
    </joint>
    <joint name="firstlink_Revolute-2" type="revolute">
        <origin xyz="-0.02 0.0 0.06299999999999999" rpy="-0.0 -1.5707963267948966 0" />
        <parent link="firstlink" />
        <child link="secondlink" />
        <axis xyz="0.0 0.0 1.0" />
        <limit lower="-1.570796" upper="1.570796" effort="1000000" velocity="1000000" />
    </joint>
    <joint name="secondlink_Revolute-3" type="revolute">
        <origin xyz="0.13400000000000004 0.0 0.0" rpy="3.141592653589793 -0.0 0.0" />
        <parent link="secondlink" />
        <child link="thirdlink" />
        <axis xyz="0.0 0.0 1.0" />
        <limit lower="-1.570796" upper="1.570796" effort="1000000" velocity="1000000" />
    </joint>
    <joint name="thirdlink_Revolute-4" type="revolute">
        <origin xyz="0.1 0.0 0.02" rpy="3.141592653589793 -0.0 0.0" />
        <parent link="thirdlink" />
        <child link="forthlink" />
        <axis xyz="0.0 0.0 1.0" />
        <limit lower="-1.570796" upper="1.570796" effort="1000000" velocity="1000000" />
    </joint>
    <joint name="forthlink_Revolute-5" type="continuous">
        <origin xyz="0.12175280999999999 0.02191061 0.02" rpy="-0.645771823237902 1.5707963267948966 0" />
        <parent link="forthlink" />
        <child link="endeffector" />
        <axis xyz="0.0 -3.1335094780038375e-07 1.0000003773603798" />
    </joint>
</robot>